<?xml version="1.0" ?>

<robot name="rb1_robot">

    <gazebo reference="base_link">
        <material>Gazebo/Black</material>
    </gazebo>

    <gazebo reference="right_wheel">
        <material>Gazebo/Grey</material>
        <mu1>1</mu1>
        <mu2>1</mu2>
    </gazebo>

    <gazebo reference="left_wheel">
        <material>Gazebo/Grey</material>
        <mu1>1</mu1>
        <mu2>1</mu2>
    </gazebo>

    <gazebo reference="front_caster">
        <material>Gazebo/Grey</material>
        <mu1>0</mu1>
        <mu2>0</mu2>
    </gazebo>

    <gazebo reference="back_caster">
        <material>Gazebo/Grey</material>
        <mu1>0</mu1>
        <mu2>0</mu2>
    </gazebo>

    <gazebo reference="front_laser">
        <material>Gazebo/Blue</material>
        <sensor type="ray" name="head_hokuyo_sensor">
            <pose>0 0 0 0 0 0</pose>
            <visualize>true</visualize>
            <update_rate>20</update_rate>
            <ray>
                <scan>
                    <horizontal>
                        <samples>720</samples>
                        <resolution>1</resolution>
                        <min_angle>-1.570796</min_angle>
                        <max_angle>1.570796</max_angle>
                    </horizontal>
                </scan>
                <range>
                    <min>0.04</min>
                    <max>10.0</max>
                    <resolution>0.01</resolution>
                </range>
                <noise>
                    <type>gaussian</type>
                    <mean>0.0</mean>
                    <stddev>0.01</stddev>
                </noise>
            </ray>
            <plugin name="gazebo_ros_head_hokuyo_controller" filename="libgazebo_ros_laser.so">
                <topicName>/laser/scan</topicName>
                <frameName>sensor_laser</frameName>
            </plugin>
        </sensor>
    </gazebo>


    <gazebo>
        <plugin filename="libgazebo_ros_diff_drive.so" name="differential_drive_controller">
            <alwaysOn>true</alwaysOn>
            <updateRate>20</updateRate>
            <leftJoint>joint_base_left_wheel</leftJoint>
            <rightJoint>joint_base_right_wheel</rightJoint>
            <wheelSeparation>0.4</wheelSeparation>
            <wheelDiameter>0.05</wheelDiameter>
            <torque>10</torque>
            <commandTopic>cmd_vel</commandTopic>
            <odometryTopic>odom</odometryTopic>
            <odometryFrame>odom</odometryFrame>
            <robotBaseFrame>base_link</robotBaseFrame>
        </plugin>
    </gazebo>

    <!-- Base_footprint -->
    <link name="base_footprint"/>

    <joint name="joint_base_footprint_base_link" type="fixed">
        <parent link="base_footprint"/>
        <child link="base_link"/>
        <origin xyz="0 0 0.15" rpy="0 0 0"/>
    </joint>

    <!-- Link - base_link -->
    <link name="base_link">
        <inertial>
            <mass value="16" />
            <origin xyz="0 0 0" rpy="0 0 0" />
            <inertia ixx="0.37" ixy="0" ixz="0" iyy="0.37" iyz="0" izz="0.5" />
        </inertial>

        <collision>
            <geometry>
                <cylinder length="0.3" radius="0.25"/>
            </geometry>
        </collision>

        <visual>
            <geometry>
                <cylinder length="0.3" radius="0.25"/>
            </geometry>

            <material name="blue">
                <color rgba="0 0 1 0.4"/>
            </material>
        </visual>
    </link>

    <joint name="joint_base_right_wheel" type="continuous">
        <parent link="base_link"/>
        <child link="right_wheel"/>
        <origin rpy="0 0 0"  xyz="0 -0.2 -0.15"/>        
        <axis rpy="0 0 0" xyz="0 1 0"/>
        <joint_properties damping="1.0" friction="1.0" />
    </joint>

    <!-- Link right_wheel -->
    <link name="right_wheel">
        <inertial>
            <mass value="3" />
            <origin xyz="0 0 0" rpy="0 0 0"/>
            <inertia ixx="0.0009375" ixy="0" ixz="0" iyy="0.00296875" iyz="0" izz="0.00296875" />
        </inertial>

        <collision>
            <origin rpy="1.5707 0 0" xyz="0 0 0" />
            <geometry>
                <cylinder length="0.1" radius="0.025" />
            </geometry>
        </collision>

        <visual>
            <origin rpy="1.5707 0 0" xyz="0 0 0" />
            <geometry>
                <cylinder length="0.1" radius="0.025" />
            </geometry>
            <material name="red">
                <color rgba="1 0 0 0.8"/>
            </material>
        </visual>

    </link>

    <joint name="joint_base_left_wheel" type="continuous">
        <parent link="base_link"/>
        <child link="left_wheel"/>
        <origin rpy="0 0 0"  xyz="0 0.2 -0.15"/>        
        <axis rpy="0 0 0" xyz="0 1 0"/>
        <joint_properties damping="1.0" friction="1.0" />
    </joint>

    <!-- Link left_wheel -->
    <link name="left_wheel">
        <inertial>
            <mass value="3" />
            <origin xyz="0 0 0" rpy="0 0 0"/>
            <inertia ixx="0.0009375" ixy="0" ixz="0" iyy="0.00296875" iyz="0" izz="0.00296875" />
        </inertial>

        <collision>
            <origin rpy="-1.5707 0 0" xyz="0 0 0"/>
            <geometry>
                <cylinder length="0.1" radius="0.025" />
            </geometry>
        </collision>


        <visual>
            <origin rpy="-1.5707 0 0" xyz="0 0 0"/>
            <geometry>
                <cylinder length="0.1" radius="0.025" />
            </geometry>
            <material name="red">
                <color rgba="1 0 0 0.8"/>
            </material>
        </visual>

    </link>

    <joint name="joint_base_link_front_caster" type="fixed">
        <parent link="base_link" />
        <child link="front_caster" />
        <origin rpy="0 0 0" xyz="0.1 0 -0.15" />
        <joint_properties damping="1.0" friction="1.0" />
    </joint>

    <!-- Link front_caster -->
    <link name="front_caster">
        <inertial>
            <mass value="1.25" />
            <origin xyz="0 0 0" rpy="0 0 0"/>
            <inertia ixx="0.0003125" ixy="0" ixz="0" iyy="0.0003125" iyz="0" izz="0.0003125"/>            
        </inertial>

        <collision>
            <origin rpy="0 0 0" xyz="0 0 0"/>
            <geometry>
                <sphere radius="0.025"/>
            </geometry>
        </collision>

        <visual>
            <origin rpy="0 0 0" xyz="0 0 0"/>
            <geometry>
                <sphere radius="0.025"/>
            </geometry>
        </visual>
    </link>

    <joint name="joint_base_link_back_caster" type="fixed">
        <parent link="base_link" />
        <child link="back_caster" />
        <origin rpy="0 0 0" xyz="-0.1 0 -0.15" />
        <joint_properties damping="1.0" friction="1.0" />
    </joint>

    <!-- Link back_caster -->
    <link name="back_caster">
        <inertial>
            <mass value="1.25" />
            <origin xyz="0 0 0" rpy="0 0 0"/>
            <inertia ixx="0.0003125" ixy="0" ixz="0" iyy="0.0003125" iyz="0" izz="0.0003125"/>            
        </inertial>

        <collision>
            <origin rpy="0 0 0" xyz="0 0 0"/>
            <geometry>
                <sphere radius="0.025"/>
            </geometry>
        </collision>

        <visual>
            <origin rpy="0 0 0" xyz="0 0 0"/>
            <geometry>
                <sphere radius="0.025"/>
            </geometry>
        </visual>
    </link>

    <joint name="joint_base_link_front_laser" type="fixed">
        <parent link="base_link"/>
        <child link="front_laser"/>
        <origin rpy="3.1416 0 0" xyz="0.25 0 0.075"/>
    </joint>

    <!-- Link front_laser -->
    <link name="front_laser">
        <inertial>
            <mass value="0.5" />
            <origin xyz="0 0 0" rpy="0 0 0"/>
            <inertia ixx="0.0000667" ixy="0" ixz="0" iyy="0.0000667" iyz="0" izz="0.0002"/>         
        </inertial>
        <collision>
            <origin rpy="0 0 0" xyz="0 0 0"/>
            <geometry>
                <cylinder length="0.02" radius="0.02"/>
            </geometry>
        </collision>

        <visual>
            <origin rpy="0 0 0" xyz="0 0 0"/>
            <geometry>
                <cylinder length="0.02" radius="0.02"/>
            </geometry>
        </visual>
    </link>

</robot>